<?xml version="1.0" encoding="utf-8"?>
<!-- This URDF was automatically created by SolidWorks to URDF Exporter! Originally created by Stephen Brawner (brawner@gmail.com) 
     Commit Version: 1.6.0-4-g7f85cfe  Build Version: 1.6.7995.38578
     For more information, please see http://wiki.ros.org/sw_urdf_exporter -->
<robot
  name="Exported_Assembly.SLDASM">
  <link
    name="base_link">
    <inertial>
      <origin
        xyz="0.0290215926434994 0.0700398197688096 0.081883994635714"
        rpy="0 0 0" />
      <mass
        value="0.217589477444393" />
      <inertia
        ixx="0.000193883281944355"
        ixy="5.47609099327043E-06"
        ixz="-4.83809279842046E-06"
        iyy="0.000274479555678797"
        iyz="-4.53735136079865E-06"
        izz="0.000204288318976544" />
    </inertial>
    <visual>
      <origin
        xyz="0 0 0"
        rpy="0 0 0" />
      <geometry>
        <mesh
          filename="package://Exported_Assembly.SLDASM/meshes/base_link.STL" />
      </geometry>
      <material
        name="">
        <color
          rgba="1 1 1 1" />
      </material>
    </visual>
    <collision>
      <origin
        xyz="0 0 0"
        rpy="0 0 0" />
      <geometry>
        <mesh
          filename="package://Exported_Assembly.SLDASM/meshes/base_link.STL" />
      </geometry>
    </collision>
  </link>
  <link
    name="Link_One">
    <inertial>
      <origin
        xyz="-0.0621304545883271 0.0503460976120289 -0.0162506507334427"
        rpy="0 0 0" />
      <mass
        value="0.171861392385501" />
      <inertia
        ixx="6.86224238455235E-05"
        ixy="2.82453652408165E-07"
        ixz="-0.000105758399024818"
        iyy="0.00043769898048304"
        iyz="6.36246325617278E-10"
        izz="0.000390557174525798" />
    </inertial>
    <visual>
      <origin
        xyz="0 0 0"
        rpy="0 0 0" />
      <geometry>
        <mesh
          filename="package://Exported_Assembly.SLDASM/meshes/Link_One.STL" />
      </geometry>
      <material
        name="">
        <color
          rgba="0.250980392156863 0.250980392156863 0.250980392156863 1" />
      </material>
    </visual>
    <collision>
      <origin
        xyz="0 0 0"
        rpy="0 0 0" />
      <geometry>
        <mesh
          filename="package://Exported_Assembly.SLDASM/meshes/Link_One.STL" />
      </geometry>
    </collision>
  </link>
  <joint
    name="Prismatic_J2"
    type="fixed">
    <origin
      xyz="-0.00945401068847282 -0.107218554049707 0.111452198088611"
      rpy="0.964964093415914 1.5707963267949 0" />
    <parent
      link="base_link" />
    <child
      link="Link_One" />
    <axis
      xyz="0 0 0" />
  </joint>
  <link
    name="Line_Two">
    <inertial>
      <origin
        xyz="-0.0287997193806698 -0.0303482733500582 -4.12124644667278E-05"
        rpy="0 0 0" />
      <mass
        value="0.121340714185467" />
      <inertia
        ixx="2.75282354680034E-05"
        ixy="1.09593451162947E-06"
        ixz="-2.17610165259665E-07"
        iyy="0.000123948102991276"
        iyz="1.02187724670186E-08"
        izz="0.000114549963563042" />
    </inertial>
    <visual>
      <origin
        xyz="0 0 0"
        rpy="0 0 0" />
      <geometry>
        <mesh
          filename="package://Exported_Assembly.SLDASM/meshes/Line_Two.STL" />
      </geometry>
      <material
        name="">
        <color
          rgba="1 1 1 1" />
      </material>
    </visual>
    <collision>
      <origin
        xyz="0 0 0"
        rpy="0 0 0" />
      <geometry>
        <mesh
          filename="package://Exported_Assembly.SLDASM/meshes/Line_Two.STL" />
      </geometry>
    </collision>
  </link>
  <joint
    name="Prismatic_J3"
    type="continuous">
    <origin
      xyz="-0.144270275080453 0 -0.0404792028992657"
      rpy="0 -1.05426056463251 3.14159265358979" />
    <parent
      link="Link_One" />
    <child
      link="Line_Two" />
    <axis
      xyz="0 1 0" />
  </joint>
  <link
    name="Link_Three">
    <inertial>
      <origin
        xyz="-0.00500307703042197 -0.00129218034156517 0.0459555100110903"
        rpy="0 0 0" />
      <mass
        value="0.02933122034538" />
      <inertia
        ixx="5.81093825999491E-06"
        ixy="-4.76164782458143E-09"
        ixz="1.70904888107207E-08"
        iyy="6.55480406407056E-06"
        iyz="4.28590767368025E-07"
        izz="3.47643769058007E-06" />
    </inertial>
    <visual>
      <origin
        xyz="0 0 0"
        rpy="0 0 0" />
      <geometry>
        <mesh
          filename="package://Exported_Assembly.SLDASM/meshes/Link_Three.STL" />
      </geometry>
      <material
        name="">
        <color
          rgba="1 1 1 1" />
      </material>
    </visual>
    <collision>
      <origin
        xyz="0 0 0"
        rpy="0 0 0" />
      <geometry>
        <mesh
          filename="package://Exported_Assembly.SLDASM/meshes/Link_Three.STL" />
      </geometry>
    </collision>
  </link>
  <joint
    name="Prismatic_J4"
    type="continuous">
    <origin
      xyz="-0.078264678389686 -0.0330500000000051 0.00509999999999927"
      rpy="1.57079632679486 -1.53047133805223 -1.57079632679486" />
    <parent
      link="Line_Two" />
    <child
      link="Link_Three" />
    <axis
      xyz="0 0 1" />
  </joint>
  <link
    name="Gripper">
    <inertial>
      <origin
        xyz="0.0327739387252827 0.0056100890572815 0.0106066546620863"
        rpy="0 0 0" />
      <mass
        value="0.0541246456457806" />
      <inertia
        ixx="5.40337626099384E-06"
        ixy="-7.1377615111053E-07"
        ixz="4.53030877135582E-07"
        iyy="1.24745396288085E-05"
        iyz="5.96567502551352E-08"
        izz="9.54622535827784E-06" />
    </inertial>
    <visual>
      <origin
        xyz="0 0 0"
        rpy="0 0 0" />
      <geometry>
        <mesh
          filename="package://Exported_Assembly.SLDASM/meshes/Gripper.STL" />
      </geometry>
      <material
        name="">
        <color
          rgba="0.752941176470588 0.752941176470588 0.752941176470588 1" />
      </material>
    </visual>
    <collision>
      <origin
        xyz="0 0 0"
        rpy="0 0 0" />
      <geometry>
        <mesh
          filename="package://Exported_Assembly.SLDASM/meshes/Gripper.STL" />
      </geometry>
    </collision>
  </link>
  <joint
    name="Prismatic_J5"
    type="continuous">
    <origin
      xyz="-0.00510000000000396 0 0.0558353216103228"
      rpy="-1.5707963267949 -0.983919180392106 3.14159265358979" />
    <parent
      link="Link_Three" />
    <child
      link="Gripper" />
    <axis
      xyz="0 0 1" />
  </joint>
</robot>